Workbook

Sheet Category Pivot
A1: country | B1: (All)
A3: Sum of id | B3: Column Labels
A4: Row Labels | B4: canceled | C4: failed | D4: live | E4: successful | F4: Grand Total
A5: food | B5: 51410 | C5: 299190 | D5: 13941 | E5: 81679 | F5: 446220
A6: games | C6: 211310 | E6: 178840 | F6: 390150
A7: journalism | B7: 25236 | F7: 25236
A8: music | B8: 24670 | C8: 140780 | D8: 33810 | E8: 937810 | F8: 1137070
A9: photography | C9: 204774 | E9: 149256 | F9: 354030
A10: publishing | B10: 45965 | C10: 222689 | E10: 86060 | F10: 354714
A11: technology | B11: 287867 | C11: 206628 | E11: 438065 | F11: 932560
A12: theater | B12: 128973 | C12: 1771451 | D12: 73118 | E12: 2711979 | F12: 4685521
A13: film & video | B13: 5580 | C13: 62910 | E13: 66450 | F13: 134940
A14: Grand Total | B14: 569701 | C14: 3119732 | D14: 120869 | E14: 4650139 | F14: 8460441

Sheet State Pivot
A1: country | B1: (All)
A2: Category | B2: (All)
A4: Sum of id | B4: Column Labels
A5: Row Labels | B5: canceled | C5: failed | D5: live | E5: successful | F5: Grand Total
A6: animation | C6: 46950 | F6: 46950
A7: art books | B7: 31410 | F7: 31410
A8: audio | B8: 25236 | F8: 25236
A9: children's books | C9: 110420 | F9: 110420
A10: classical music | E10: 101620 | F10: 101620
A11: documentary | E11: 59310 | F11: 59310
A12: drama | C12: 15960 | F12: 15960
A13: electronic music | E13: 64800 | F13: 64800
A14: faith | C14: 68820 | D14: 33810 | F14: 102630
A15: fiction | C15: 45200 | F15: 45200
A16: food trucks | B16: 51410 | C16: 248980 | F16: 300390
A17: gadgets | C17: 38210 | F17: 38210
A18: hardware | E18: 296270 | F18: 296270
A19: indie rock | C19: 17790 | E19: 305870 | F19: 323660
A20: jazz | C20: 54170 | F20: 54170
A21: makerspaces | C21: 29425 | E21: 23985 | F21: 53410
A22: metal | E22: 16990 | F22: 16990
A23: mobile games | C23: 60080 | F23: 60080
A24: musical | B24: 77550 | C24: 212650 | E24: 209310 | F24: 499510
A25: nature | C25: 31010 | F25: 31010
A26: nonfiction | E26: 56650 | F26: 56650
A27: people | C27: 39810 | F27: 39810
A28: photobooks | C28: 102144 | E28: 149256 | F28: 251400
A29: places | C29: 31810 | F29: 31810
A30: plays | C30: 1313361 | D30: 59603 | E30: 2250889 | F30: 3623853
A31: pop | E31: 66420 | F31: 66420
A32: radio & podcasts | E32: 29410 | F32: 29410
A33: restaurants | C33: 50210 | F33: 50210
A34: rock | E34: 382110 | F34: 382110
A35: science fiction | B35: 5580 | F35: 5580
A36: shorts | E36: 5370 | F36: 5370
A37: small batch | D37: 13941 | E37: 81679 | F37: 95620
A38: space exploration | B38: 47727 | C38: 5283 | E38: 104820 | F38: 157830
A39: spaces | B39: 51423 | C39: 245440 | D39: 13515 | E39: 251780 | F39: 562158
A40: tabletop games | E40: 178840 | F40: 178840
A41: television | E41: 1770 | F41: 1770
...

Sheet Date Pivot
A1: Category | B1: (All)
A2: Years | B2: (All)
A4: Count of state | B4: Column Labels
A5: Row Labels | B5: canceled | C5: failed | D5: live | E5: successful | F5: Grand Total
A6: Jan | B6: 34 | C6: 149 | D6: 2 | E6: 182 | F6: 367
A7: Feb | B7: 27 | C7: 106 | D7: 18 | E7: 202 | F7: 353
A8: Mar | B8: 28 | C8: 108 | D8: 30 | E8: 180 | F8: 346
A9: Apr | B9: 27 | C9: 102 | E9: 192 | F9: 321
A10: May | B10: 26 | C10: 126 | E10: 234 | F10: 386
A11: Jun | B11: 27 | C11: 147 | E11: 211 | F11: 385
A12: Jul | B12: 43 | C12: 150 | E12: 194 | F12: 387
A13: Aug | B13: 33 | C13: 134 | E13: 166 | F13: 333
A14: Sep | B14: 24 | C14: 127 | E14: 147 | F14: 298
A15: Oct | B15: 20 | C15: 149 | E15: 183 | F15: 352
A16: Nov | B16: 37 | C16: 114 | E16: 183 | F16: 334
A17: Dec | B17: 23 | C17: 118 | E17: 111 | F17: 252
A18: Grand Total | B18: 349 | C18: 1530 | D18: 50 | E18: 2185 | F18: 4114

Sheet Bonus Outcome Based on Goal
A1: Goal | B1: Number Successful | C1: Number Failed | D1: Number Canceled | E1: Total Projects | F1: Percentage Successful | G1: Percentage Failed | H1: Percentage Canceled
A2: Less than 1000 | B2: =COUNTIFS(DataSet!$F:$F, "successful", DataSet!$D:$D, "<1000") -> 322 | C2: =COUNTIFS(DataSet!$F:$F, "failed", DataSet!$D:$D, "<1000") -> 113 | D2: =COUNTIFS(DataSet!$F:$F, "canceled", DataSet!$D:$D, "<1000") -> 18 | E2: =SUM(B2:D2) -> 453 | F2: =B2/E2 -> 0.71081678 | G2: =C2/E2 -> 0.24944812 | H2: =D2/E2 -> 0.039735099
A3: 1000 to 4999 | B3: =COUNTIFS(DataSet!$F:$F, "successful", DataSet!$D:$D, ">=1000", DataSet!$D:$D, "<=4999") -> 932 | C3: =COUNTIFS(DataSet!$F:$F, "failed", DataSet!$D:$D, ">=1000", DataSet!$D:$D, "<=4999") -> 420 | D3: =COUNTIFS(DataSet!$F:$F, "canceled", DataSet!$D:$D, ">=1000", DataSet!$D:$D, "<=4999") -> 60 | E3: =SUM(B3:D3) -> 1412 | F3: =B3/E3 -> 0.66005666 | G3: =C3/E3 -> 0.29745042 | H3: =D3/E3 -> 0.042492918
A4: 5000 to 9999 | B4: =COUNTIFS(DataSet!$F:$F, "successful", DataSet!$D:$D, ">=5000", DataSet!$D:$D, "<=9999") -> 381 | C4: =COUNTIFS(DataSet!$F:$F, "failed", DataSet!$D:$D, ">=5000", DataSet!$D:$D, "<=9999") -> 283 | D4: =COUNTIFS(DataSet!$F:$F, "canceled", DataSet!$D:$D, ">=5000", DataSet!$D:$D, "<=9999") -> 52 | E4: =SUM(B4:D4) -> 716 | F4: =B4/E4 -> 0.53212291 | G4: =C4/E4 -> 0.3952514 | H4: =D4/E4 -> 0.072625698
A5: 10000 to 14999 | B5: =COUNTIFS(DataSet!$F:$F, "successful", DataSet!$D:$D, ">=10000", DataSet!$D:$D, "<=14999") -> 168 | C5: =COUNTIFS(DataSet!$F:$F, "failed", DataSet!$D:$D, ">=10000", DataSet!$D:$D, "<=14999") -> 144 | D5: =COUNTIFS(DataSet!$F:$F, "canceled", DataSet!$D:$D, ">=10000", DataSet!$D:$D, "<=14999") -> 40 | E5: =SUM(B5:D5) -> 352 | F5: =B5/E5 -> 0.47727273 | G5: =C5/E5 -> 0.40909091 | H5: =D5/E5 -> 0.11363636
A6: 15000 to 19999 | B6: =COUNTIFS(DataSet!$F:$F, "successful", DataSet!$D:$D, ">=15000", DataSet!$D:$D, "<=19999") -> 94 | C6: =COUNTIFS(DataSet!$F:$F, "failed", DataSet!$D:$D, ">=15000", DataSet!$D:$D, "<=19999") -> 90 | D6: =COUNTIFS(DataSet!$F:$F, "canceled", DataSet!$D:$D, ">=15000", DataSet!$D:$D, "<=19999") -> 17 | E6: =SUM(B6:D6) -> 201 | F6: =B6/E6 -> 0.46766169 | G6: =C6/E6 -> 0.44776119 | H6: =D6/E6 -> 0.084577114
A7: 20000 to 24999 | B7: =COUNTIFS(DataSet!$F:$F, "successful", DataSet!$D:$D, ">=20000", DataSet!$D:$D, "<=24999") -> 62 | C7: =COUNTIFS(DataSet!$F:$F, "failed", DataSet!$D:$D, ">=20000", DataSet!$D:$D, "<=24999") -> 72 | D7: =COUNTIFS(DataSet!$F:$F, "canceled", DataSet!$D:$D, ">=20000", DataSet!$D:$D, "<=24999") -> 14 | E7: =SUM(B7:D7) -> 148 | F7: =B7/E7 -> 0.41891892 | G7: =C7/E7 -> 0.48648649 | H7: =D7/E7 -> 0.094594595
A8: 25000 to 29999 | B8: =COUNTIFS(DataSet!$F:$F, "successful", DataSet!$D:$D, ">=25000", DataSet!$D:$D, "<=29999") -> 55 | C8: =COUNTIFS(DataSet!$F:$F, "failed", DataSet!$D:$D, ">=25000", DataSet!$D:$D, "<=29999") -> 64 | D8: =COUNTIFS(DataSet!$F:$F, "canceled", DataSet!$D:$D, ">=25000", DataSet!$D:$D, "<=29999") -> 18 | E8: =SUM(B8:D8) -> 137 | F8: =B8/E8 -> 0.40145985 | G8: =C8/E8 -> 0.46715328 | H8: =D8/E8 -> 0.13138686
A9: 30000 to 34999 | B9: =COUNTIFS(DataSet!$F:$F, "successful", DataSet!$D:$D, ">=30000", DataSet!$D:$D, "<=34999") -> 32 | C9: =COUNTIFS(DataSet!$F:$F, "failed", DataSet!$D:$D, ">=30000", DataSet!$D:$D, "<=34999") -> 37 | D9: =COUNTIFS(DataSet!$F:$F, "canceled", DataSet!$D:$D, ">=30000", DataSet!$D:$D, "<=34999") -> 13 | E9: =SUM(B9:D9) -> 82 | F9: =B9/E9 -> 0.3902439 | G9: =C9/E9 -> 0.45121951 | H9: =D9/E9 -> 0.15853659
A10: 35000 to 39999 | B10: =COUNTIFS(DataSet!$F:$F, "successful", DataSet!$D:$D, ">=35000", DataSet!$D:$D, "<=39999") -> 26 | C10: =COUNTIFS(DataSet!$F:$F, "failed", DataSet!$D:$D, ">=35000", DataSet!$D:$D, "<=39999") -> 22 | D10: =COUNTIFS(DataSet!$F:$F, "canceled", DataSet!$D:$D, ">=35000", DataSet!$D:$D, "<=39999") -> 7 | E10: =SUM(B10:D10) -> 55 | F10: =B10/E10 -> 0.47272727 | G10: =C10/E10 -> 0.4 | H10: =D10/E10 -> 0.12727273
A11: 40000 to 44999 | B11: =COUNTIFS(DataSet!$F:$F, "successful", DataSet!$D:$D, ">=40000", DataSet!$D:$D, "<=44999") -> 21 | C11: =COUNTIFS(DataSet!$F:$F, "failed", DataSet!$D:$D, ">=40000", DataSet!$D:$D, "<=44999") -> 16 | D11: =COUNTIFS(DataSet!$F:$F, "canceled", DataSet!$D:$D, ">=40000", DataSet!$D:$D, "<=44999") -> 6 | E11: =SUM(B11:D11) -> 43 | F11: =B11/E11 -> 0.48837209 | G11: =C11/E11 -> 0.37209302 | H11: =D11/E11 -> 0.13953488
A12: 45000 to 49999 | B12: =COUNTIFS(DataSet!$F:$F, "successful", DataSet!$D:$D, ">=45000", DataSet!$D:$D, "<=49999") -> 6 | C12: =COUNTIFS(DataSet!$F:$F, "failed", DataSet!$D:$D, ">=45000", DataSet!$D:$D, "<=49999") -> 11 | D12: =COUNTIFS(DataSet!$F:$F, "canceled", DataSet!$D:$D, ">=45000", DataSet!$D:$D, "<=49999") -> 4 | E12: =SUM(B12:D12) -> 21 | F12: =B12/E12 -> 0.28571429 | G12: =C12/E12 -> 0.52380952 | H12: =D12/E12 -> 0.19047619
A13: Greater than or equal to 50000 | B13: =COUNTIFS(DataSet!F:F, "successful", DataSet!E:E, ">=50000") -> 147 | C13: =COUNTIFS(DataSet!F:F, "failed", DataSet!E:E, ">=50000") -> 6 | D13: =COUNTIFS(DataSet!F:F, "canceled", DataSet!E:E, ">=50000") -> 9 | E13: =SUM(B13:D13) -> 162 | F13: =B13/E13 -> 0.90740741 | G13: =C13/E13 -> 0.037037037 | H13: =D13/E13 -> 0.055555556

Sheet Statistical Analysis
A1: state | B1: backers_count | D1: Successful Statistical Analysis | H1: state | I1: backers_count | K1: Failed Statistical Analysis
A2: successful | B2: 1 | D2: Mean | E2: =AVERAGE(B2:B2186) -> 194.42517 | H2: failed | I2: 0 | K2: Mean | L2: =AVERAGE(I2:I2186) -> 17.709804
A3: successful | B3: 1 | D3: Median | E3: =MEDIAN(B2:B2186) -> 62 | H3: failed | I3: 0 | K3: Median | L3: =MEDIAN(I2:I2186) -> 4
A4: successful | B4: 1 | D4: Minimum | E4: =MIN(B2:B2186) -> 1 | H4: failed | I4: 0 | K4: Minimum | L4: =MIN(I2:I2186) -> 0
A5: successful | B5: 2 | D5: Maximum | E5: =MAX(B2:B2186) -> 26457 | H5: failed | I5: 0 | K5: Maximum | L5: =MAX(I2:I2186) -> 1293
A6: successful | B6: 3 | D6: Variance | E6: =_xlfn.VAR.P(B2:B2186) -> 712840.99 | H6: failed | I6: 0 | K6: Variance | L6: =_xlfn.VAR.P(I2:I1531) -> 3773.2217
A7: successful | B7: 3 | D7: Standard Deviation | E7: =_xlfn.STDEV.P(B2:B2186) -> 844.29911 | H7: failed | I7: 0 | K7: Standard Deviation | L7: =_xlfn.STDEV.P(I2:I1531) -> 61.426555
A8: successful | B8: 3 | H8: failed | I8: 0
A9: successful | B9: 3 | H9: failed | I9: 0
A10: successful | B10: 3 | H10: failed | I10: 0 | K10: The mean doesn't accurately describe the middle of our dataset because the number of backers jumps significantly higher.
A11: successful | B11: 3 | H11: failed | I11: 0 | K11: Utilizing the variance the sucessful is far from the Mean which tells me that dataset is disproportioned in backers.
A12: successful | B12: 3 | H12: failed | I12: 0
A13: successful | B13: 3 | H13: failed | I13: 0
A14: successful | B14: 3 | H14: failed | I14: 0
A15: successful | B15: 3 | H15: failed | I15: 0
A16: successful | B16: 4 | H16: failed | I16: 0
A17: successful | B17: 4 | H17: failed | I17: 0
A18: successful | B18: 4 | H18: failed | I18: 0
A19: successful | B19: 4 | H19: failed | I19: 0
A20: successful | B20: 4 | H20: failed | I20: 0
A21: successful | B21: 5 | H21: failed | I21: 0
A22: successful | B22: 5 | H22: failed | I22: 0
A23: successful | B23: 5 | H23: failed | I23: 0
... A1531: successful | B1531: 112 | H1531: failed | I1531: 1293
A1532: successful | B1532: 112
A1533: successful | B1533: 112
A1534: successful | B1534: 113
A1535: successful | B1535: 113
A1536: successful | B1536: 113
A1537: successful | B1537: 113
A1538: successful | B1538: 113
A1539: successful | B1539: 113
A1540: successful | B1540: 113
A1541: successful | B1541: 113
A1542: successful | B1542: 114
A1543: successful | B1543: 114
... A2186: successful | B2186: 26457

Sheet DataSet
A1: id | B1: name | C1: blurb | D1: goal | E1: pledged | F1: state | G1: country | H1: currency | I1: deadline | J1: launched_at | K1: staff_pick | L1: backers_count | M1: spotlight | N1: Category and Sub-Category | O1: Percent Funded | P1: Average Donation | Q1: Category | R1: Sub-Category | S1: Date Created Conversion | T1: Date End Conversion
A2: 847 | B2: CENTROPYMUSIC | C2: MUSIC WITH MEANING! MUSIC THAT MATTERS!!! | D2: 10 | E2: 10 | F2: successful | G2: US | H2: USD | I2: 1436555376 | J2: 1433963376 | K2: FALSE | L2: 1 | M2: TRUE | N2: music/metal | O2: =ROUND((E2/D2)*100,0) -> 100 | P2: =E2/L2 -> 10 | Q2: =LEFT(N2,SEARCH("/",N2)-1) -> music | R2: =RIGHT(N2,LEN(N2)-SEARCH("/",N2,1)) -> metal | S2: =(((J2/60)/60)/24)+DATE(1970,1,1) -> 42165.798 | T2: =(((I2/60)/60)/24)+DATE(1970,1,1) -> 42195.798
A3: 2213 | B3: WINTER WALK WITH ME ~ Hasenfang Album | C3: NOTE: THIS PROJECT IS ALREADY 100% FUNDED!!! This is an "Extended Campaign Run" for anyone who wants a CD of my seventh solo album. | D3: 5 | E3: 10 | F3: successful | G3: US | H3: USD | I3: 1431719379 | J3: 1429127379 | K3: FALSE | L3: 1 | M3: TRUE | N3: music/electronic music | O3: =ROUND((E3/D3)*100,0) -> 200 | P3: =E3/L3 -> 10 | Q3: =LEFT(N3,SEARCH("/",N3)-1) -> music | R3: =RIGHT(N3,LEN(N3)-SEARCH("/",N3,1)) -> electronic music | S3: =(((J3/60)/60)/24)+DATE(1970,1,1) -> 42109.826 | T3: =(((I3/60)/60)/24)+DATE(1970,1,1) -> 42139.826
A4: 31 | B4: The Alan Katz Show | C4: After a two-year hiatus, The Alan Katz Show is coming back! But it can't unless we can get a 16gb flash drive valued at $12.71! | D4: 13 | E4: 13 | F4: successful | G4: US | H4: USD | I4: 1453748434 | J4: 1452193234 | K4: FALSE | L4: 1 | M4: TRUE | N4: film & video/television | O4: =ROUND((E4/D4)*100,0) -> 100 | P4: =E4/L4 -> 13 | Q4: =LEFT(N4,SEARCH("/",N4)-1) -> film & video | R4: =RIGHT(N4,LEN(N4)-SEARCH("/",N4,1)) -> television | S4: =(((J4/60)/60)/24)+DATE(1970,1,1) -> 42376.792 | T4: =(((I4/60)/60)/24)+DATE(1970,1,1) -> 42394.792
A5: 3600 | B5: Pariah | C5: The First Play From The Man Who Brought You The Black James Bond! | D5: 10 | E5: 13 | F5: successful | G5: US | H5: USD | I5: 1476390164 | J5: 1473970964 | K5: FALSE | L5: 4 | M5: TRUE | N5: theater/plays | O5: =ROUND((E5/D5)*100,0) -> 130 | P5: =E5/L5 -> 3.25 | Q5: =LEFT(N5,SEARCH("/",N5)-1) -> theater | R5: =RIGHT(N5,LEN(N5)-SEARCH("/",N5,1)) -> plays | S5: =(((J5/60)/60)/24)+DATE(1970,1,1) -> 42628.849 | T5: =(((I5/60)/60)/24)+DATE(1970,1,1) -> 42656.849
A6: 2536 | B6: Become the subject of my next composition! | C6: I create my solo piano Vignettes by encrypting someone's name in the melody. Next up is the fourth Vignette, and I need a subject! | D6: 25 | E6: 29 | F6: successful | G6: US | H6: USD | I6: 1375151566 | J6: 1373337166 | K6: FALSE | L6: 4 | M6: TRUE | N6: music/classical music | O6: =ROUND((E6/D6)*100,0) -> 116 | P6: =E6/L6 -> 7.25 | Q6: =LEFT(N6,SEARCH("/",N6)-1) -> music | R6: =RIGHT(N6,LEN(N6)-SEARCH("/",N6,1)) -> classical music | S6: =(((J6/60)/60)/24)+DATE(1970,1,1) -> 41464.106 | T6: =(((I6/60)/60)/24)+DATE(1970,1,1) -> 41485.106
A7: 1755 | B7: Just One Block: The Extraordinary Journey Around The Block | C7: For about a year I've been taking pictures while walking around the block with my dog. Want to publish a ebook of what I captured. | D7: 25 | E7: 30 | F7: successful | G7: US | H7: USD | I7: 1444071361 | J7: 1441479361 | K7: FALSE | L7: 4 | M7: TRUE | N7: photography/photobooks | O7: =ROUND((E7/D7)*100,0) -> 120 | P7: =E7/L7 -> 7.5 | Q7: =LEFT(N7,SEARCH("/",N7)-1) -> photography | R7: =RIGHT(N7,LEN(N7)-SEARCH("/",N7,1)) -> photobooks | S7: =(((J7/60)/60)/24)+DATE(1970,1,1) -> 42252.789 | T7: =(((I7/60)/60)/24)+DATE(1970,1,1) -> 42282.789
A8: 732 | B8: Chess puzzles in your pocket: a new eBook | C8: A great collection of puzzles to take and enjoy anywhere in the world - have fun, challenge yourself, and become a better chess player! | D8: 40 | E8: 64 | F8: successful | G8: GB | H8: GBP | I8: 1380449461 | J8: 1375265461 | K8: FALSE | L8: 13 | M8: TRUE | N8: publishing/nonfiction | O8: =ROUND((E8/D8)*100,0) -> 160 | P8: =E8/L8 -> 4.9230769 | Q8: =LEFT(N8,SEARCH("/",N8)-1) -> publishing | R8: =RIGHT(N8,LEN(N8)-SEARCH("/",N8,1)) -> nonfiction | S8: =(((J8/60)/60)/24)+DATE(1970,1,1) -> 41486.424 | T8: =(((I8/60)/60)/24)+DATE(1970,1,1) -> 41546.424
A9: 3840 | B9: Tonight I'll be April | C9: A gritty play looking at a modern day relationship, highlighting issues of mental health and abuse suffered by men. | D9: 1 | E9: 65 | F9: successful | G9: GB | H9: GBP | I9: 1459180229 | J9: 1457023829 | K9: FALSE | L9: 3 | M9: TRUE | N9: theater/plays | O9: =ROUND((E9/D9)*100,0) -> 6500 | P9: =E9/L9 -> 21.666667 | Q9: =LEFT(N9,SEARCH("/",N9)-1) -> theater | R9: =RIGHT(N9,LEN(N9)-SEARCH("/",N9,1)) -> plays | S9: =(((J9/60)/60)/24)+DATE(1970,1,1) -> 42432.702 | T9: =(((I9/60)/60)/24)+DATE(1970,1,1) -> 42457.66
A10: 3675 | B10: Memoir of a Forgotten Past | C10: 3 decades, 3 generations, 3 friends, one house. Real Eyes Theatre explore how our lives are influenced by the decades we grow up in. | D10: 50 | E10: 70 | F10: successful | G10: GB | H10: GBP | I10: 1463353200 | J10: 1462285182 | K10: FALSE | L10: 3 | M10: TRUE | N10: theater/plays | O10: =ROUND((E10/D10)*100,0) -> 140 | P10: =E10/L10 -> 23.333333 | Q10: =LEFT(N10,SEARCH("/",N10)-1) -> theater | R10: =RIGHT(N10,LEN(N10)-SEARCH("/",N10,1)) -> plays | S10: =(((J10/60)/60)/24)+DATE(1970,1,1) -> 42493.597 | T10: =(((I10/60)/60)/24)+DATE(1970,1,1) -> 42505.958
A11: 2794 | B11: Dusk Theatre Company presents... Macbeth Rebothered | C11: Dusk Theatre have created a brand new adaptation of the hilarious BBC4 comedy "Macbeth Rebothered" originally by The Penny Dreadfuls. | D11: 50 | E11: 75 | F11: successful | G11: GB | H11: GBP | I11: 1457031600 | J11: 1455640559 | K11: FALSE | L11: 3 | M11: TRUE | N11: theater/plays | O11: =ROUND((E11/D11)*100,0) -> 150 | P11: =E11/L11 -> 25 | Q11: =LEFT(N11,SEARCH("/",N11)-1) -> theater | R11: =RIGHT(N11,LEN(N11)-SEARCH("/",N11,1)) -> plays | S11: =(((J11/60)/60)/24)+DATE(1970,1,1) -> 42416.692 | T11: =(((I11/60)/60)/24)+DATE(1970,1,1) -> 42432.792
A12: 3576 | B12: Vote for Next Season's Shows! | C12: Vote here for whatever show you want to see next year! No gimmick, no stretch goals, just a simple vote and a free ticket. | D12: 100 | E12: 100 | F12: successful | G12: US | H12: USD | I12: 1480947054 | J12: 1475759454 | K12: FALSE | L12: 5 | M12: TRUE | N12: theater/plays | O12: =ROUND((E12/D12)*100,0) -> 100 | P12: =E12/L12 -> 20 | Q12: =LEFT(N12,SEARCH("/",N12)-1) -> theater | R12: =RIGHT(N12,LEN(N12)-SEARCH("/",N12,1)) -> plays | S12: =(((J12/60)/60)/24)+DATE(1970,1,1) -> 42649.549 | T12: =(((I12/60)/60)/24)+DATE(1970,1,1) -> 42709.591
A13: 640 | B13: Carbon mini bikes / race / MTB / FAT ~ Carbon tow placement | C13: Mountain, fat and race bikes made from high grade aero carbon fibers by tow placement and tow folding technology (no fibres cutting). | D13: 70 | E13: 101 | F13: successful | G13: FR | H13: EUR | I13: 1480028400 | J13: 1478685915 | K13: FALSE | L13: 2 | M13: TRUE | N13: technology/wearables | O13: =ROUND((E13/D13)*100,0) -> 144 | P13: =E13/L13 -> 50.5 | Q13: =LEFT(N13,SEARCH("/",N13)-1) -> technology | R13: =RIGHT(N13,LEN(N13)-SEARCH("/",N13,1)) -> wearables | S13: =(((J13/60)/60)/24)+DATE(1970,1,1) -> 42683.42 | T13: =(((I13/60)/60)/24)+DATE(1970,1,1) -> 42698.958
... A2109: 116 | B2109: Villanelle | C2109: Villanelle is a feature film that blends elements of classic, hardboiled Film Noir, with classic Horror and tells a great story to boot | D2109: 3500 | E2109: 3978 | F2109: successful | G2109: US | H2109: USD | I2109: 1302260155 | J2109: 1298289355 | K2109: FALSE | L2109: 57 | M2109: TRUE | N2109: film & video/shorts | O2109: =ROUND((E2109/D2109)*100,0) -> 114 | P2109: =E2109/L2109 -> 69.789474 | Q2109: =LEFT(N2109,SEARCH("/",N2109)-1) -> film & video | R2109: =RIGHT(N2109,LEN(N2109)-SEARCH("/",N2109,1)) -> shorts | S2109: =(((J2109/60)/60)/24)+DATE(1970,1,1) -> 40595.497 | T2109: =(((I2109/60)/60)/24)+DATE(1970,1,1) -> 40641.455
A2110: 244 | B2110: 39756 | C2110: A transmedia-project to amass a library of footage shot the day Obama was elected, for (1) a feature documentary, (2) an interactive web history | D2110: 3500 | E2110: 3981.5 | F2110: successful | G2110: US | H2110: USD | I2110: 1268723160 | J2110: 1265269559 | K2110: TRUE | L2110: 84 | M2110: TRUE | N2110: film & video/documentary | O2110: =ROUND((E2110/D2110)*100,0) -> 114 | P2110: =E2110/L2110 -> 47.39881 | Q2110: =LEFT(N2110,SEARCH("/",N2110)-1) -> film & video | R2110: =RIGHT(N2110,LEN(N2110)-SEARCH("/",N2110,1)) -> documentary | S2110: =(((J2110/60)/60)/24)+DATE(1970,1,1) -> 40213.324 | T2110: =(((I2110/60)/60)/24)+DATE(1970,1,1) -> 40253.296
A2111: 531 | B2111: COMPASS PLAYERS presents SYLVIA by A. R. Gurney | C2111: SYLVIA is a modern romantic comedy about a marriage and a talking dog. Directed by Jeanna Michaels. January 12 through January 29, 2017 | D2111: 4000 | E2111: 4000 | F2111: successful | G2111: US | H2111: USD | I2111: 1481957940 | J2111: 1478050429 | K2111: FALSE | L2111: 31 | M2111: TRUE | N2111: theater/plays | O2111: =ROUND((E2111/D2111)*100,0) -> 100 | P2111: =E2111/L2111 -> 129.03226 | Q2111: =LEFT(N2111,SEARCH("/",N2111)-1) -> theater | R2111: =RIGHT(N2111,LEN(N2111)-SEARCH("/",N2111,1)) -> plays | S2111: =(((J2111/60)/60)/24)+DATE(1970,1,1) -> 42676.065 | T2111: =(((I2111/60)/60)/24)+DATE(1970,1,1) -> 42721.291
A2112: 3049 | B2112: Pickerington Community Theatre's Set Capabilities Expansion | C2112: Pickerington Community Theatre is seeking donations to purchase a Pipe & Drape system to increase staging possibilities for the company | D2112: 3750 | E2112: 4000 | F2112: successful | G2112: US | H2112: USD | I2112: 1434241255 | J2112: 1431649255 | K2112: FALSE | L2112: 54 | M2112: TRUE | N2112: theater/spaces | O2112: =ROUND((E2112/D2112)*100,0) -> 107 | P2112: =E2112/L2112 -> 74.074074 | Q2112: =LEFT(N2112,SEARCH("/",N2112)-1) -> theater | R2112: =RIGHT(N2112,LEN(N2112)-SEARCH("/",N2112,1)) -> spaces | S2112: =(((J2112/60)/60)/24)+DATE(1970,1,1) -> 42139.015 | T2112: =(((I2112/60)/60)/24)+DATE(1970,1,1) -> 42169.015
A2113: 3517 | B2113: A Bright Room Called Day by Tony Kushner | C2113: Support an outstanding cast of actors to take on a professional production of a masterpiece of modern theatre | D2113: 4000 | E2113: 4000 | F2113: successful | G2113: GB | H2113: GBP | I2113: 1404471600 | J2113: 1401910634 | K2113: FALSE | L2113: 13 | M2113: TRUE | N2113: theater/plays | O2113: =ROUND((E2113/D2113)*100,0) -> 100 | P2113: =E2113/L2113 -> 307.69231 | Q2113: =LEFT(N2113,SEARCH("/",N2113)-1) -> theater | R2113: =RIGHT(N2113,LEN(N2113)-SEARCH("/",N2113,1)) -> plays | S2113: =(((J2113/60)/60)/24)+DATE(1970,1,1) -> 41794.818 | T2113: =(((I2113/60)/60)/24)+DATE(1970,1,1) -> 41824.458
A2114: 3492 | B2114: The Man from Willow's Brook, a new play by Kevin Kordis | C2114: We have the Blackbox Fellowship at Boston Playwright's Theatre, now all we need is your support to produce Kevin's new play! | D2114: 3800 | E2114: 4000.22 | F2114: successful | G2114: US | H2114: USD | I2114: 1445818397 | J2114: 1442794397 | K2114: FALSE | L2114: 35 | M2114: TRUE | N2114: theater/plays | O2114: =ROUND((E2114/D2114)*100,0) -> 105 | P2114: =E2114/L2114 -> 114.292 | Q2114: =LEFT(N2114,SEARCH("/",N2114)-1) -> theater | R2114: =RIGHT(N2114,LEN(N2114)-SEARCH("/",N2114,1)) -> plays | S2114: =(((J2114/60)/60)/24)+DATE(1970,1,1) -> 42268.009 | T2114: =(((I2114/60)/60)/24)+DATE(1970,1,1) -> 42303.009
A2115: 82 | B2115: "T IS FOR TANTRUM" - HORROR/COMEDY | C2115: A short film about the tragically hilarious events that occur when a fearful and panicky 6-year old boy loses his first baby tooth. | D2115: 4000 | E2115: 4000.5 | F2115: successful | G2115: US | H2115: USD | I2115: 1318189261 | J2115: 1315597261 | K2115: FALSE | L2115: 100 | M2115: TRUE | N2115: film & video/shorts | O2115: =ROUND((E2115/D2115)*100,0) -> 100 | P2115: =E2115/L2115 -> 40.005 | Q2115: =LEFT(N2115,SEARCH("/",N2115)-1) -> film & video | R2115: =RIGHT(N2115,LEN(N2115)-SEARCH("/",N2115,1)) -> shorts | S2115: =(((J2115/60)/60)/24)+DATE(1970,1,1) -> 40795.82 | T2115: =(((I2115/60)/60)/24)+DATE(1970,1,1) -> 40825.82
A2116: 3602 | B2116: Red Lion Theatre Presents Shakespeare's Macbeth | C2116: A student directed and student performed production of Shakespeare's Macbeth in Milwaukee's beautiful Lake Park on June 3rd & 4th | D2116: 4000 | E2116: 4002 | F2116: successful | G2116: US | H2116: USD | I2116: 1463520479 | J2116: 1458336479 | K2116: FALSE | L2116: 49 | M2116: TRUE | N2116: theater/plays | O2116: =ROUND((E2116/D2116)*100,0) -> 100 | P2116: =E2116/L2116 -> 81.673469 | Q2116: =LEFT(N2116,SEARCH("/",N2116)-1) -> theater | R2116: =RIGHT(N2116,LEN(N2116)-SEARCH("/",N2116,1)) -> plays | S2116: =(((J2116/60)/60)/24)+DATE(1970,1,1) -> 42447.894 | T2116: =(((I2116/60)/60)/24)+DATE(1970,1,1) -> 42507.894
A2117: 3301 | B2117: right left with heels: US Premiere at City Garage | C2117: The US premiere of the controversial new Polish play the authorities don't want you to see, staged by an award-winning director. | D2117: 3000 | E2117: 4004 | F2117: successful | G2117: US | H2117: USD | I2117: 1470034740 | J2117: 1466185176 | K2117: FALSE | L2117: 70 | M2117: TRUE | N2117: theater/plays | O2117: =ROUND((E2117/D2117)*100,0) -> 133 | P2117: =E2117/L2117 -> 57.2 | Q2117: =LEFT(N2117,SEARCH("/",N2117)-1) -> theater | R2117: =RIGHT(N2117,LEN(N2117)-SEARCH("/",N2117,1)) -> plays | S2117: =(((J2117/60)/60)/24)+DATE(1970,1,1) -> 42538.736 | T2117: =(((I2117/60)/60)/24)+DATE(1970,1,1) -> 42583.291
A2118: 3695 | B2118: The History Boys at USC | C2118: Tony-Award Winning Play, The History Boys brought to you by the Independent Student Production Company Narrative Series: Page to Stage! | D2118: 4000 | E2118: 4005 | F2118: successful | G2118: US | H2118: USD | I2118: 1421009610 | J2118: 1419281610 | K2118: FALSE | L2118: 33 | M2118: TRUE | N2118: theater/plays | O2118: =ROUND((E2118/D2118)*100,0) -> 100 | P2118: =E2118/L2118 -> 121.36364 | Q2118: =LEFT(N2118,SEARCH("/",N2118)-1) -> theater | R2118: =RIGHT(N2118,LEN(N2118)-SEARCH("/",N2118,1)) -> plays | S2118: =(((J2118/60)/60)/24)+DATE(1970,1,1) -> 41995.87 | T2118: =(((I2118/60)/60)/24)+DATE(1970,1,1) -> 42015.87
A2119: 2081 | B2119: Our Vintage Film: Summer Tour Kickstarter | C2119: Embarking on a Summer Tour to spread their message of cherishing your unforgettable memories through nostalgic rock music. | D2119: 3500 | E2119: 4010 | F2119: successful | G2119: US | H2119: USD | I2119: 1337144340 | J2119: 1333597555 | K2119: FALSE | L2119: 55 | M2119: TRUE | N2119: music/indie rock | O2119: =ROUND((E2119/D2119)*100,0) -> 115 | P2119: =E2119/L2119 -> 72.909091 | Q2119: =LEFT(N2119,SEARCH("/",N2119)-1) -> music | R2119: =RIGHT(N2119,LEN(N2119)-SEARCH("/",N2119,1)) -> indie rock | S2119: =(((J2119/60)/60)/24)+DATE(1970,1,1) -> 41004.157 | T2119: =(((I2119/60)/60)/24)+DATE(1970,1,1) -> 41045.208
A2120: 3234 | B2120: Repetitive Beats: A new play premiering at Vault Festival | C2120: Get Repetitive Beats to Vaults! A high octane play set in Oxford during one of the most influential & hedonistic movements in music. | D2120: 4000 | E2120: 4015.71 | F2120: successful | G2120: GB | H2120: GBP | I2120: 1485991860 | J2120: 1483124208 | K2120: FALSE | L2120: 115 | M2120: TRUE | N2120: theater/plays | O2120: =ROUND((E2120/D2120)*100,0) -> 100 | P2120: =E2120/L2120 -> 34.919217 | Q2120: =LEFT(N2120,SEARCH("/",N2120)-1) -> theater | R2120: =RIGHT(N2120,LEN(N2120)-SEARCH("/",N2120,1)) -> plays | S2120: =(((J2120/60)/60)/24)+DATE(1970,1,1) -> 42734.789 | T2120: =(((I2120/60)/60)/24)+DATE(1970,1,1) -> 42767.98
A2121: 1288 | B2121: "The Rounds" by Justin Moriarty, presented by EggSalad | C2121: EggSalad presents an unflinching new work mapping the mental landscape of addiction and recovery. Premiering in NY Aug 26-27 & Sept 2! | D2121: 4000 | E2121: 4018 | F2121: successful | G2121: US | H2121: USD | I2121: 1470801600 | J2121: 1468122163 | K2121: FALSE | L2121: 61 | M2121: TRUE | N2121: theater/plays | O2121: =ROUND((E2121/D2121)*100,0) -> 100 | P2121: =E2121/L2121 -> 65.868852 | Q2121: =LEFT(N2121,SEARCH("/",N2121)-1) -> theater | R2121: =RIGHT(N2121,LEN(N2121)-SEARCH("/",N2121,1)) -> plays | S2121: =(((J2121/60)/60)/24)+DATE(1970,1,1) -> 42561.155 | T2121: =(((I2121/60)/60)/24)+DATE(1970,1,1) -> 42592.167
A2122: 798 | B2122: Eric Stuart Band 4 Song EP "Character" | C2122: We have some great new songs and want to record a special edition 4 song EP as our next Eric Stuart Band release | D2122: 3500 | E2122: 4021 | F2122: successful | G2122: US | H2122: USD | I2122: 1412086187 | J2122: 1409494187 | K2122: FALSE | L2122: 87 | M2122: TRUE | N2122: music/rock | O2122: =ROUND((E2122/D2122)*100,0) -> 115 | P2122: =E2122/L2122 -> 46.218391 | Q2122: =LEFT(N2122,SEARCH("/",N2122)-1) -> music | R2122: =RIGHT(N2122,LEN(N2122)-SEARCH("/",N2122,1)) -> rock | S2122: =(((J2122/60)/60)/24)+DATE(1970,1,1) -> 41882.59 | T2122: =(((I2122/60)/60)/24)+DATE(1970,1,1) -> 41912.59
... A3887: 3885 | B3887: THE SESSIONS - The Beatles at Abbey Road Studios (Canceled) | C3887: A LIVE musical spectacular theatrical experience of The Beatles recording sessions at Abbey Road Studios. | D3887: 375000 | E3887: 0 | F3887: canceled | G3887: US | H3887: USD | I3887: 1462834191 | J3887: 1460242191 | K3887: FALSE | L3887: 0 | M3887: FALSE | N3887: theater/musical | O3887: =ROUND((E3887/D3887)*100,0) -> 0 | P3887: =E3887/L3887 -> #DIV/0! | Q3887: =LEFT(N3887,SEARCH("/",N3887)-1) -> theater | R3887: =RIGHT(N3887,LEN(N3887)-SEARCH("/",N3887,1)) -> musical | S3887: =(((J3887/60)/60)/24)+DATE(1970,1,1) -> 42469.951 | T3887: =(((I3887/60)/60)/24)+DATE(1970,1,1) -> 42499.951
A3888: 3886 | B3888: a (Canceled) | C3888: 1 | D3888: 10000 | E3888: 0 | F3888: canceled | G3888: AU | H3888: AUD | I3888: 1418275702 | J3888: 1415683702 | K3888: FALSE | L3888: 0 | M3888: FALSE | N3888: theater/musical | O3888: =ROUND((E3888/D3888)*100,0) -> 0 | P3888: =E3888/L3888 -> #DIV/0! | Q3888: =LEFT(N3888,SEARCH("/",N3888)-1) -> theater | R3888: =RIGHT(N3888,LEN(N3888)-SEARCH("/",N3888,1)) -> musical | S3888: =(((J3888/60)/60)/24)+DATE(1970,1,1) -> 41954.228 | T3888: =(((I3888/60)/60)/24)+DATE(1970,1,1) -> 41984.228
A3889: 3887 | B3889: SUPER!: An Original Musical (KC Fringe 2015) (Canceled) | C3889: "SUPER!: An Original Musical" is an original work written by Ryan Hruza. This campaign is to fund the production and pay the cast/crew! | D3889: 2000 | E3889: 35 | F3889: canceled | G3889: US | H3889: USD | I3889: 1430517600 | J3889: 1426538129 | K3889: FALSE | L3889: 2 | M3889: FALSE | N3889: theater/musical | O3889: =ROUND((E3889/D3889)*100,0) -> 2 | P3889: =E3889/L3889 -> 17.5 | Q3889: =LEFT(N3889,SEARCH("/",N3889)-1) -> theater | R3889: =RIGHT(N3889,LEN(N3889)-SEARCH("/",N3889,1)) -> musical | S3889: =(((J3889/60)/60)/24)+DATE(1970,1,1) -> 42079.858 | T3889: =(((I3889/60)/60)/24)+DATE(1970,1,1) -> 42125.917
A3890: 3888 | B3890: Popinjay Productions' The Odyssey | C3890: We are devising a vibrant new adaptation of Homer's The Odyssey featuring dynamic storytelling, stunning visuals and original music. | D3890: 2000 | E3890: 542 | F3890: failed | G3890: GB | H3890: GBP | I3890: 1488114358 | J3890: 1485522358 | K3890: FALSE | L3890: 14 | M3890: FALSE | N3890: theater/plays | O3890: =ROUND((E3890/D3890)*100,0) -> 27 | P3890: =E3890/L3890 -> 38.714286 | Q3890: =LEFT(N3890,SEARCH("/",N3890)-1) -> theater | R3890: =RIGHT(N3890,LEN(N3890)-SEARCH("/",N3890,1)) -> plays | S3890: =(((J3890/60)/60)/24)+DATE(1970,1,1) -> 42762.546 | T3890: =(((I3890/60)/60)/24)+DATE(1970,1,1) -> 42792.546
A3891: 3889 | B3891: Sherri's Playhouse Present's A Heavenly Hand! | C3891: A romantic comedy about a girl trying to figure out what to do with her life and an angel who comes to help her. | D3891: 8000 | E3891: 118 | F3891: failed | G3891: US | H3891: USD | I3891: 1420413960 | J3891: 1417651630 | K3891: FALSE | L3891: 9 | M3891: FALSE | N3891: theater/plays | O3891: =ROUND((E3891/D3891)*100,0) -> 1 | P3891: =E3891/L3891 -> 13.111111 | Q3891: =LEFT(N3891,SEARCH("/",N3891)-1) -> theater | R3891: =RIGHT(N3891,LEN(N3891)-SEARCH("/",N3891,1)) -> plays | S3891: =(((J3891/60)/60)/24)+DATE(1970,1,1) -> 41977.005 | T3891: =(((I3891/60)/60)/24)+DATE(1970,1,1) -> 42008.976
A3892: 3890 | B3892: Something Wicked This Way Comes | C3892: Will Power Troupe is the only US group invited to perform in London's Shakespeare Festival. We need your help to bring the USA to UK! | D3892: 15000 | E3892: 2524 | F3892: failed | G3892: US | H3892: USD | I3892: 1439662344 | J3892: 1434478344 | K3892: FALSE | L3892: 8 | M3892: FALSE | N3892: theater/plays | O3892: =ROUND((E3892/D3892)*100,0) -> 17 | P3892: =E3892/L3892 -> 315.5 | Q3892: =LEFT(N3892,SEARCH("/",N3892)-1) -> theater | R3892: =RIGHT(N3892,LEN(N3892)-SEARCH("/",N3892,1)) -> plays | S3892: =(((J3892/60)/60)/24)+DATE(1970,1,1) -> 42171.759 | T3892: =(((I3892/60)/60)/24)+DATE(1970,1,1) -> 42231.759
A3893: 3891 | B3893: Out of the Box: A Mime Story | C3893: A comedy about a mime who dreams of becoming a stand up comedian. | D3893: 800 | E3893: 260 | F3893: failed | G3893: US | H3893: USD | I3893: 1427086740 | J3893: 1424488244 | K3893: FALSE | L3893: 7 | M3893: FALSE | N3893: theater/plays | O3893: =ROUND((E3893/D3893)*100,0) -> 33 | P3893: =E3893/L3893 -> 37.142857 | Q3893: =LEFT(N3893,SEARCH("/",N3893)-1) -> theater | R3893: =RIGHT(N3893,LEN(N3893)-SEARCH("/",N3893,1)) -> plays | S3893: =(((J3893/60)/60)/24)+DATE(1970,1,1) -> 42056.132 | T3893: =(((I3893/60)/60)/24)+DATE(1970,1,1) -> 42086.208
A3894: 3892 | B3894: The Sea Horse, presented by Different Stages | C3894: Saloon owner Gertude Blum mistrusts all men and scorns love, but sailor Harry Bales' romantic dreams force her to face her tragic past. | D3894: 1000 | E3894: 0 | F3894: failed | G3894: US | H3894: USD | I3894: 1408863600 | J3894: 1408203557 | K3894: FALSE | L3894: 0 | M3894: FALSE | N3894: theater/plays | O3894: =ROUND((E3894/D3894)*100,0) -> 0 | P3894: =E3894/L3894 -> #DIV/0! | Q3894: =LEFT(N3894,SEARCH("/",N3894)-1) -> theater | R3894: =RIGHT(N3894,LEN(N3894)-SEARCH("/",N3894,1)) -> plays | S3894: =(((J3894/60)/60)/24)+DATE(1970,1,1) -> 41867.652 | T3894: =(((I3894/60)/60)/24)+DATE(1970,1,1) -> 41875.292
A3895: 3893 | B3895: MY PRIVATE REVOLUTION | C3895: An inspiring story of a young girl's journey from childhood to adulthood told through monologue, dialogue, poetry and music and dance. | D3895: 50000 | E3895: 10775 | F3895: failed | G3895: US | H3895: USD | I3895: 1404194400 | J3895: 1400600840 | K3895: FALSE | L3895: 84 | M3895: FALSE | N3895: theater/plays | O3895: =ROUND((E3895/D3895)*100,0) -> 22 | P3895: =E3895/L3895 -> 128.27381 | Q3895: =LEFT(N3895,SEARCH("/",N3895)-1) -> theater | R3895: =RIGHT(N3895,LEN(N3895)-SEARCH("/",N3895,1)) -> plays | S3895: =(((J3895/60)/60)/24)+DATE(1970,1,1) -> 41779.658 | T3895: =(((I3895/60)/60)/24)+DATE(1970,1,1) -> 41821.25
A3896: 3894 | B3896: MADE-UP: A Sitcom Theater Special | C3896: Ryan and Vanessa are hosting Christmas for the first time but instead of a happy celebration, they get a hilarious survival situation. | D3896: 15000 | E3896: 520 | F3896: failed | G3896: US | H3896: USD | I3896: 1481000340 | J3896: 1478386812 | K3896: FALSE | L3896: 11 | M3896: FALSE | N3896: theater/plays | O3896: =ROUND((E3896/D3896)*100,0) -> 3 | P3896: =E3896/L3896 -> 47.272727 | Q3896: =LEFT(N3896,SEARCH("/",N3896)-1) -> theater | R3896: =RIGHT(N3896,LEN(N3896)-SEARCH("/",N3896,1)) -> plays | S3896: =(((J3896/60)/60)/24)+DATE(1970,1,1) -> 42679.958 | T3896: =(((I3896/60)/60)/24)+DATE(1970,1,1) -> 42710.208
A3897: 3895 | B3897: Vestige | C3897: A Transgender makeup artist calls into question the loyalty of her best friend in a 1980's circus while dealing with her dying mother. | D3897: 1000 | E3897: 50 | F3897: failed | G3897: US | H3897: USD | I3897: 1425103218 | J3897: 1422424818 | K3897: FALSE | L3897: 1 | M3897: FALSE | N3897: theater/plays | O3897: =ROUND((E3897/D3897)*100,0) -> 5 | P3897: =E3897/L3897 -> 50 | Q3897: =LEFT(N3897,SEARCH("/",N3897)-1) -> theater | R3897: =RIGHT(N3897,LEN(N3897)-SEARCH("/",N3897,1)) -> plays | S3897: =(((J3897/60)/60)/24)+DATE(1970,1,1) -> 42032.25 | T3897: =(((I3897/60)/60)/24)+DATE(1970,1,1) -> 42063.25
A3898: 3896 | B3898: Yorick and Company | C3898: Yorick and Co. is a comedy about a struggling theatre company whose mysterious benefactor starts haunting the show! | D3898: 1600 | E3898: 170 | F3898: failed | G3898: US | H3898: USD | I3898: 1402979778 | J3898: 1401770178 | K3898: FALSE | L3898: 4 | M3898: FALSE | N3898: theater/plays | O3898: =ROUND((E3898/D3898)*100,0) -> 11 | P3898: =E3898/L3898 -> 42.5 | Q3898: =LEFT(N3898,SEARCH("/",N3898)-1) -> theater | R3898: =RIGHT(N3898,LEN(N3898)-SEARCH("/",N3898,1)) -> plays | S3898: =(((J3898/60)/60)/24)+DATE(1970,1,1) -> 41793.192 | T3898: =(((I3898/60)/60)/24)+DATE(1970,1,1) -> 41807.192
A3899: 3897 | B3899: Terry Pratchett's Wyrd Sisters at Paeroa Little Theatre | C3899: Help us to put on a production of Terry Pratchett's Wyrd Sisters, an ambitions show for our theatre but one I believe we can do. | D3899: 2500 | E3899: 440 | F3899: failed | G3899: NZ | H3899: NZD | I3899: 1420750683 | J3899: 1418158683 | K3899: FALSE | L3899: 10 | M3899: FALSE | N3899: theater/plays | O3899: =ROUND((E3899/D3899)*100,0) -> 18 | P3899: =E3899/L3899 -> 44 | Q3899: =LEFT(N3899,SEARCH("/",N3899)-1) -> theater | R3899: =RIGHT(N3899,LEN(N3899)-SEARCH("/",N3899,1)) -> plays | S3899: =(((J3899/60)/60)/24)+DATE(1970,1,1) -> 41982.874 | T3899: =(((I3899/60)/60)/24)+DATE(1970,1,1) -> 42012.874
...
